<?xml version="1.0" encoding="utf-8"?>
<!-- This URDF was automatically created by SolidWorks to URDF Exporter! Originally created by Stephen Brawner (brawner@gmail.com) 
     Commit Version: 1.6.0-4-g7f85cfe  Build Version: 1.6.7995.38578
     For more information, please see http://wiki.ros.org/sw_urdf_exporter -->
<robot
  name="wheel_urdf">
  <link
    name="base_link">
    <inertial>
      <origin
        xyz="-3.8995E-05 -3.8995E-05 0.085394"
        rpy="0 0 0" />
      <mass
        value="0.25668" />
      <inertia
        ixx="0.0010715"
        ixy="-2.2059E-13"
        ixz="-7.2465E-13"
        iyy="0.0010951"
        iyz="1.8044E-13"
        izz="0.00014309" />
    </inertial>
    <visual>
      <origin
        xyz="0 0 0"
        rpy="0 0 0" />
      <geometry>
        <mesh
          filename="package://wheel_urdf/meshes/base_link.STL" />
      </geometry>
      <material
        name="">
        <color
          rgba="1 1 1 1" />
      </material>
    </visual>
    <collision>
      <origin
        xyz="0 0 0"
        rpy="0 0 0" />
      <geometry>
        <mesh
          filename="package://wheel_urdf/meshes/base_link.STL" />
      </geometry>
    </collision>
  </link>
  <link
    name="link1">
    <inertial>
      <origin
        xyz="7.20560763833866E-15 0.0091204066607712 0.0288697436850635"
        rpy="0 0 0" />
      <mass
        value="0.0384691172749358" />
      <inertia
        ixx="1.34245733950468E-05"
        ixy="2.4633028927843E-18"
        ixz="9.25597534203361E-22"
        iyy="5.20692486512084E-06"
        iyz="-8.88927054089203E-22"
        izz="1.65468488047905E-05" />
    </inertial>
    <visual>
      <origin
        xyz="0 0 0"
        rpy="0 0 0" />
      <geometry>
        <mesh
          filename="package://wheel_urdf/meshes/link1.STL" />
      </geometry>
      <material
        name="">
        <color
          rgba="1 1 1 1" />
      </material>
    </visual>
    <collision>
      <origin
        xyz="0 0 0"
        rpy="0 0 0" />
      <geometry>
        <mesh
          filename="package://wheel_urdf/meshes/link1.STL" />
      </geometry>
    </collision>
  </link>
  <joint
    name="joint1"
    type="continuous">
    <origin
      xyz="-0.000100023615882267 -0.000100023615882305 0.3168"
      rpy="0 0 0" />
    <parent
      link="base_link" />
    <child
      link="link1" />
    <axis
      xyz="0 0 1" />
  </joint>
  <link
    name="link2">
    <inertial>
      <origin
        xyz="-0.000422193996269133 0.0359020285324367 0.0350217407298871"
        rpy="0 0 0" />
      <mass
        value="0.588570543422523" />
      <inertia
        ixx="0.000868335490113796"
        ixy="3.47805827710633E-07"
        ixz="1.49885346337489E-07"
        iyy="0.00101129602560427"
        iyz="-4.79978162007259E-06"
        izz="0.000221816791970069" />
    </inertial>
    <visual>
      <origin
        xyz="0 0 0"
        rpy="0 0 0" />
      <geometry>
        <mesh
          filename="package://wheel_urdf/meshes/link2.STL" />
      </geometry>
      <material
        name="">
        <color
          rgba="0.592156862745098 0.666666666666667 0.682352941176471 1" />
      </material>
    </visual>
    <collision>
      <origin
        xyz="0 0 0"
        rpy="0 0 0" />
      <geometry>
        <mesh
          filename="package://wheel_urdf/meshes/link2.STL" />
      </geometry>
    </collision>
  </link>
  <joint
    name="joint2"
    type="continuous">
    <origin
      xyz="0 0.0339999999999989 0.0462"
      rpy="0 0 0" />
    <parent
      link="link1" />
    <child
      link="link2" />
    <axis
      xyz="0 1 0" />
  </joint>
  <link
    name="wheel_link">
    <inertial>
      <origin
        xyz="-8.34835672813838E-17 8.32667268468867E-17 -3.69267234448523E-06"
        rpy="0 0 0" />
      <mass
        value="0.51812017798115" />
      <inertia
        ixx="0.00109375279298174"
        ixy="-7.37363974077291E-19"
        ixz="2.35655177615068E-17"
        iyy="0.00109375279298174"
        iyz="-1.62630325872826E-19"
        izz="0.00217888072418342" />
    </inertial>
    <visual>
      <origin
        xyz="0 0 0"
        rpy="0 0 0" />
      <geometry>
        <mesh
          filename="package://wheel_urdf/meshes/wheel_link.STL" />
      </geometry>
      <material
        name="">
        <color
          rgba="0.647058823529412 0.619607843137255 0.588235294117647 1" />
      </material>
    </visual>
    <collision>
      <origin
        xyz="0 0 0"
        rpy="0 0 0" />
      <geometry>
        <mesh
          filename="package://wheel_urdf/meshes/wheel_link.STL" />
      </geometry>
    </collision>
  </link>
  <joint
    name="wheel_joint"
    type="continuous">
    <origin
      xyz="0 0.073146 -0.13735"
      rpy="-2.0944 0 0" />
    <parent
      link="link2" />
    <child
      link="wheel_link" />
    <axis
      xyz="0 0 -1" />
  </joint>
</robot>